<?xml version="1.0"?>
<robot
  name="panel">
  <link
    name="world">
  </link>
  <joint
    name="world_joint"
    type="fixed">
    <origin
      xyz="0 0 0.5"
      rpy="0 0 0" />
    <parent
      link="world" />
    <child
      link="panel_base_link" />
  </joint>
  <link
    name="panel_base_link">
    <inertial>
      <origin
        xyz="-0.059734 0.0071587 -0.022133"
        rpy="0 0 0" />
      <mass
        value="14.025" />
      <inertia
        ixx="1"
        ixy="0"
        ixz="0"
        iyy="1"
        iyz="0"
        izz="1" />
    </inertial>
    <visual>
      <origin
        xyz="0 0 0"
        rpy="0 0 0" />
      <geometry>
        <mesh
          filename="package://panel/meshes/base_link.STL" />
      </geometry>
      <material
        name="">
        <color
          rgba="0.0 0.0 0.93333 1" />
      </material>
    </visual>
    <collision>
      <origin
        xyz="0 0 0"
        rpy="0 0 0" />
      <geometry>
        <mesh
          filename="package://panel/meshes/base_link.STL" />
      </geometry>
    </collision>
  </link>
  <link
    name="case_cover_link">
    <inertial>
      <origin
        xyz="-0.15308 -0.03104 0.029242"
        rpy="0 0 0" />
      <mass
        value="4.5006" />
      <inertia
        ixx="1"
        ixy="0"
        ixz="0"
        iyy="1"
        iyz="0"
        izz="1" />
    </inertial>
    <visual>
      <origin
        xyz="0 0 0"
        rpy="0 0 0" />
      <geometry>
        <mesh
          filename="package://panel/meshes/case_cover_link.STL" />
      </geometry>
      <material
        name="">
        <color
          rgba="0.0 0.0 0.93333 1" />
      </material>
    </visual>
    <collision>
      <origin
        xyz="0 0 0"
        rpy="0 0 0" />
      <geometry>
        <mesh
          filename="package://panel/meshes/case_cover_link.STL" />
      </geometry>
    </collision>
  </link>
  <joint
    name="case_cover_joint"
    type="revolute">
    <origin
      xyz="0.09269 -0.0295 0.1071"
      rpy="1.5708 0 0" />
    <parent
      link="panel_base_link" />
    <child
      link="case_cover_link" />
    <axis
      xyz="0 1 0" />
    <limit
      lower="0"
      upper="2"
      effort="0"
      velocity="0" />
    <dynamics
      damping = 2
      friction = 0.1/> 
  </joint>
  <link
    name="small_shelf_link">
    <inertial>
      <origin
        xyz="-6.93889390390723E-18 -0.0178125630289301 0.0912591458081848"
        rpy="0 0 0" />
      <mass
        value="0.926162" />
      <inertia
        ixx="1"
        ixy="0"
        ixz="0"
        iyy="1"
        iyz="0"
        izz="1" />
    </inertial>
    <visual>
      <origin
        xyz="0 0 0"
        rpy="0 0 0" />
      <geometry>
        <mesh
          filename="package://panel/meshes/small_shelf_link.STL" />
      </geometry>
      <material
        name="">
        <color
          rgba="0.0 0.0 0.933333333333333 1" />
      </material>
    </visual>
    <collision>
      <origin
        xyz="0 0 0"
        rpy="0 0 0" />
      <geometry>
        <mesh
          filename="package://panel/meshes/small_shelf_link.STL" />
      </geometry>
    </collision>
  </link>
  <joint
    name="small_shelf_joint"
    type="prismatic">
    <origin
      xyz="-0.06081 -0.0975 -0.0048573"
      rpy="1.5708 0 3.1416" />
    <parent
      link="panel_base_link" />
    <child
      link="small_shelf_link" />
    <axis
      xyz="0 0 -1" />
    <limit
      lower="0"
      upper="0.1"
      effort="0"
      velocity="0" />
    <dynamics
      damping = 10
      friction = 2/> 
  </joint>
  <link
    name="large_shelf_link">
    <inertial>
      <origin
        xyz="6.93889390390723E-18 0.00201303993480031 -0.0995843520782396"
        rpy="0 0 0" />
      <mass
        value="3.23928" />
      <inertia
        ixx="1"
        ixy="0"
        ixz="0"
        iyy="1"
        iyz="0"
        izz="1" />
    </inertial>
    <visual>
      <origin
        xyz="0 0 0"
        rpy="0 0 0" />
      <geometry>
        <mesh
          filename="package://panel/meshes/large_shelf_link.STL" />
      </geometry>
      <material
        name="">
        <color
          rgba="0.792156862745098 0.819607843137255 0.933333333333333 1" />
      </material>
    </visual>
    <collision>
      <origin
        xyz="0 0 0"
        rpy="0 0 0" />
      <geometry>
        <mesh
          filename="package://panel/meshes/large_shelf_link.STL" />
      </geometry>
    </collision>
  </link>
  <joint
    name="large_shelf_joint"
    type="prismatic">
    <origin
      xyz="-0.05981 -0.1075 -0.16286"
      rpy="1.5708 0 0" />
    <parent
      link="panel_base_link" />
    <child
      link="large_shelf_link" />
    <axis
      xyz="0 0 1" />
    <limit
      lower="0"
      upper="0.1"
      effort="0"
      velocity="0" />
    <dynamics
      damping = 10
      friction = 2/> 
  </joint>
<gazebo reference="case_cover_link">
<material>Gazebo/Grey</material>
</gazebo>
<gazebo reference="panel_base_link">
<material>Gazebo/Grey</material>
</gazebo>
<gazebo reference="large_shelf_link">
<material>Gazebo/Red</material>
</gazebo>
<gazebo reference="small_shelf_link">
<material>Gazebo/Red</material>
</gazebo> 
</robot>
