<?xml version="1.0" encoding="utf-8"?>
<!-- This URDF was automatically created by SolidWorks to URDF Exporter! Originally created by Stephen Brawner (brawner@gmail.com) 
     Commit Version: 1.5.1-0-g916b5db  Build Version: 1.5.7152.31018
     For more information, please see http://wiki.ros.org/sw_urdf_exporter -->
<robot
  name="altyurur_20" xmlns:xacro="http://www.ros.org/wiki/xacro">

  <xacro:include filename="$(find rover_20_description)/urdf/vlp16.urdf.xacro"/> 
  <xacro:property name="cameraSize" value="0.05"/>
  <xacro:property name="cameraMass" value="0.1"/>

  <link
    name="base_link">
    <inertial>
      <origin
        xyz="0.036648 -0.78 -0.1149"
        rpy="0 0 0" />
      <mass
        value="7.6922" />
      <inertia
        ixx="0.16992"
        ixy="-1.2309E-05"
        ixz="0.040329"
        iyy="0.48212"
        iyz="-1.555E-07"
        izz="0.54282" />
    </inertial>
    <visual>
      <origin
        xyz="0 0 0"
        rpy="0 0 0" />
      <geometry>
        <mesh
          filename="package://rover_20_description/meshes/base_link.STL" />
      </geometry>
      <material
        name="">
        <color
          rgba="0.79216 0.81961 0.93333 1" />
      </material>
    </visual>
    <collision>
      <origin
        xyz="0 0 0"
        rpy="0 0 0" />
      <geometry>
        <mesh
          filename="package://rover_20_description/meshes/base_link.STL" />
      </geometry>
    </collision>
  </link>
  <link
    name="left_front_link">
    <inertial>
      <origin
        xyz="-3.0122E-05 0.00014177 0.082453"
        rpy="0 0 0" />
      <mass
        value="1.1573" />
      <inertia
        ixx="0.0096934"
        ixy="-5.9959E-08"
        ixz="-1.119E-06"
        iyy="0.0096827"
        iyz="2.2683E-06"
        izz="0.01783" />
    </inertial>
    <visual>
      <origin
        xyz="0 0 0"
        rpy="0 0 0" />
      <geometry>
        <mesh
          filename="package://rover_20_description/meshes/left_front_linkk.STL" />
      </geometry>
      <material
        name="">
        <color
          rgba="0.79216 0.81961 0.93333 1" />
      </material>
    </visual>
    <collision>
      <origin
        xyz="0 0 0"
        rpy="0 0 0" />
      <geometry>
        <mesh
          filename="package://rover_20_description/meshes/left_front_linkk.STL" />
      </geometry>
    </collision>
  </link>
  <joint
    name="left_front_joint"
    type="continuous">
    <origin
      xyz="0.45031 -0.2596 -0.31064"
      rpy="1.5708 1.2698 0" />
    <parent
      link="base_link" />
    <child
      link="left_front_link" />
    <axis
      xyz="0 0 -1" />
  </joint>
  <link
    name="right_front_link">
    <inertial>
      <origin
        xyz="-2.8756E-05 0.00014342 0.07551"
        rpy="0 0 0" />
      <mass
        value="1.1573" />
      <inertia
        ixx="0.0096937"
        ixy="2.8004E-07"
        ixz="-1.119E-06"
        iyy="0.0096825"
        iyz="2.2683E-06"
        izz="0.01783" />
    </inertial>
    <visual>
      <origin
        xyz="0 0 0"
        rpy="0 0 0" />
      <geometry>
        <mesh
          filename="package://rover_20_description/meshes/right_front_link.STL" />
      </geometry>
      <material
        name="">
        <color
          rgba="0.79216 0.81961 0.93333 1" />
      </material>
    </visual>
    <collision>
      <origin
        xyz="0 0 0"
        rpy="0 0 0" />
      <geometry>
        <mesh
          filename="package://rover_20_description/meshes/right_front_link.STL" />
      </geometry>
    </collision>
  </link>
  <joint
    name="right_front_joint"
    type="continuous">
    <origin
      xyz="0.45155 -1.1425 -0.31113"
      rpy="1.5708 -1.0421 0" />
    <parent
      link="base_link" />
    <child
      link="right_front_link" />
    <axis
      xyz="0 0 -1" />
  </joint>
  <link
    name="right_rear_link">
    <inertial>
      <origin
        xyz="-3.0122E-05 0.00014177 0.07551"
        rpy="0 0 0" />
      <mass
        value="1.1573" />
      <inertia
        ixx="0.0096934"
        ixy="-5.9909E-08"
        ixz="-1.119E-06"
        iyy="0.0096827"
        iyz="2.2683E-06"
        izz="0.01783" />
    </inertial>
    <visual>
      <origin
        xyz="0 0 0"
        rpy="0 0 0" />
      <geometry>
        <mesh
          filename="package://rover_20_description/meshes/right_rear_link.STL" />
      </geometry>
      <material
        name="">
        <color
          rgba="0.79216 0.81961 0.93333 1" />
      </material>
    </visual>
    <collision>
      <origin
        xyz="0 0 0"
        rpy="0 0 0" />
      <geometry>
        <mesh
          filename="package://rover_20_description/meshes/right_rear_link.STL" />
      </geometry>
    </collision>
  </link>
  <joint
    name="right_rear_joint"
    type="continuous">
    <origin
      xyz="-0.25574 -1.1425 -0.31006"
      rpy="1.5708 1.2698 0" />
    <parent
      link="base_link" />
    <child
      link="right_rear_link" />
    <axis
      xyz="0 0 -1" />
  </joint>
  <link
    name="left_rear_link">
    <inertial>
      <origin
        xyz="-2.9287E-05 0.00014265 0.082453"
        rpy="0 0 0" />
      <mass
        value="1.1573" />
      <inertia
        ixx="0.0096936"
        ixy="1.0425E-07"
        ixz="-1.119E-06"
        iyy="0.0096826"
        iyz="2.2683E-06"
        izz="0.01783" />
    </inertial>
    <visual>
      <origin
        xyz="0 0 0"
        rpy="0 0 0" />
      <geometry>
        <mesh
          filename="package://rover_20_description/meshes/left_rear_link.STL" />
      </geometry>
      <material
        name="">
        <color
          rgba="0.79216 0.81961 0.93333 1" />
      </material>
    </visual>
    <collision>
      <origin
        xyz="0 0 0"
        rpy="0 0 0" />
      <geometry>
        <mesh
          filename="package://rover_20_description/meshes/left_rear_link.STL" />
      </geometry>
    </collision>
  </link>
  <joint
    name="left_rear_joint"
    type="continuous">
    <origin
      xyz="-0.25698 -0.2596 -0.31054"
      rpy="1.5708 0.64514 0" />
    <parent
      link="base_link" />
    <child
      link="left_rear_link" />
    <axis
      xyz="0 0 -1" />
  </joint>

  <vlp16 prefix="base" topic="/velodyne_points" hz="10" samples="440" gpu="false"/>

  <joint name="base_laser_joint" type="fixed">
    <origin xyz="0.325 -0.775 -0.035" rpy="0 0 0" />
    <parent link="base_link"/>
    <child link="base_laser_mount"/>
  </joint>

  <link name="camera">
    <collision>
      <origin xyz="0 0 0" rpy="0 0 0"/>
      <geometry>
        <box size="${cameraSize} ${cameraSize} ${cameraSize}"/>
      </geometry>
    </collision>

    <visual>
      <origin xyz="0 0 0" rpy="0 0 0"/>
      <geometry>
        <box size="${cameraSize} ${cameraSize} ${cameraSize}"/>
      </geometry>
      <material name="green"/>
    </visual>

    <inertial>
      <mass value="${cameraMass}" />
      <origin xyz="0 0 0" rpy="0 0 0"/>
      <box_inertia m="${cameraMass}" x="${cameraSize}" y="${cameraSize}" z="${cameraSize}" />
      <inertia ixx="1e-6" ixy="0" ixz="0" iyy="1e-6" iyz="0" izz="1e-6" />
    </inertial>
  </link>

  <joint name="camera_joint" type="fixed">
    <axis xyz="1 1 0" />
    <origin xyz="0.325 -0.775 0.105" rpy="0 0 0"/>
    <parent link="base_link"/>
    <child link="camera"/>
  </joint>

  <transmission name="left_front_trans" type="SimpleTransmission">
    <type>transmission_interface/SimpleTransmission</type>
    <actuator name="left_front_motor">
      <mechanicalReduction>1</mechanicalReduction>
    </actuator>
    <joint name="left_front_joint">
      <hardwareInterface>hardware_interface/VelocityJointInterface</hardwareInterface>
    </joint>
  </transmission>

  <transmission name="right_front_trans" type="SimpleTransmission">
    <type>transmission_interface/SimpleTransmission</type>
    <actuator name="right_front_motor">
      <mechanicalReduction>1</mechanicalReduction>
    </actuator>
    <joint name="right_front_joint">
      <hardwareInterface>hardware_interface/VelocityJointInterface</hardwareInterface>
    </joint>
  </transmission>

  <transmission name="left_rear_trans" type="SimpleTransmission">
    <type>transmission_interface/SimpleTransmission</type>
    <actuator name="left_rear_motor">
      <mechanicalReduction>1</mechanicalReduction>
    </actuator>
    <joint name="left_rear_joint">
      <hardwareInterface>hardware_interface/VelocityJointInterface</hardwareInterface>
    </joint>
  </transmission>

  <transmission name="right_rear_trans" type="SimpleTransmission">
    <type>transmission_interface/SimpleTransmission</type>
    <actuator name="right_rear_motor">
      <mechanicalReduction>1</mechanicalReduction>
    </actuator>
    <joint name="right_rear_joint">
      <hardwareInterface>hardware_interface/VelocityJointInterface</hardwareInterface>
    </joint>
  </transmission>

  <gazebo>
    <plugin name="gazebo_ros_control" filename="libgazebo_ros_control.so">
      <robotSimType>gazebo_ros_control/DefaultRobotHWSim</robotSimType>
      <legacyModeNS>true</legacyModeNS>
    </plugin>
  </gazebo>

   <gazebo>
    <plugin name="imu_controller" filename="libhector_gazebo_ros_imu.so">
      <updateRate>50.0</updateRate>
      <bodyName>base_link</bodyName>
      <topicName>/imu/data</topicName>
      <accelDrift>0.005 0.005 0.005</accelDrift>
      <accelGaussianNoise>0.005 0.005 0.005</accelGaussianNoise>
      <rateDrift>0.005 0.005 0.005 </rateDrift>
      <rateGaussianNoise>0.005 0.005 0.005 </rateGaussianNoise>
      <headingDrift>0.005</headingDrift>[ERROR] [1555346159.311804930, 0.098000000]: 
      <headingGaussianNoise>0.005</headingGaussianNoise>
    </plugin>
  </gazebo>

  <gazebo>
    <plugin name="gps_controller" filename="libhector_gazebo_ros_gps.so">
      <updateRate>40</updateRate>
      <bodyName>base_link</bodyName>
      <frameId>base_link</frameId>
      <topicName>gps/fix</topicName>
      <velocityTopicName>navsat/vel</velocityTopicName>
      <referenceLatitude>41.1052670854</referenceLatitude>
      <referenceLongitude>29.023378124</referenceLongitude>
      <referenceHeading>0</referenceHeading>
      <referenceAltitude>0</referenceAltitude>
      <drift>0.0001 0.0001 0.0001</drift>
    </plugin>
  </gazebo>

  <gazebo reference="camera">
     <sensor type="camera" name="camera">
       <update_rate>30.0</update_rate>
       <camera name="camera">
         <horizontal_fov>1.3962634</horizontal_fov>
         <image>
           <width>800</width>
           <height>800</height>
           <format>R8G8B8</format>
         </image>
         <clip>
           <near>0.02</near>
           <far>300</far>
         </clip>
         <noise>
           <type>gaussian</type>
           <mean>0.0</mean>
           <stddev>0.007</stddev>
         </noise>
       </camera>
       <plugin name="camera_controller" filename="libgazebo_ros_camera.so">
         <alwaysOn>true</alwaysOn>
         <updateRate>0.0</updateRate>
         <cameraName>/mybot/camera</cameraName>
         <imageTopicName>camera_view</imageTopicName>
         <cameraInfoTopicName>camera_info</cameraInfoTopicName>
         <frameName>camera</frameName>
         <hackBaseline>0.07</hackBaseline>
         <distortionK1>0.0</distortionK1>
         <distortionK2>0.0</distortionK2>
         <distortionK3>0.0</distortionK3>
         <distortionT1>0.0</distortionT1>
         <distortionT2>0.0</distortionT2>
       </plugin>
     </sensor>
   </gazebo>
</robot>