<?xml version="1.0" encoding="utf-8"?>
<robot
  name="arm_description">
  
  <link
    name="base_link">
    <inertial>
      <origin
        xyz="0.784990805509548 0.637296392786603 0.699576535800332"
        rpy="0 0 0" />
      <mass
        value="92.1170480325152" />
      <inertia
        ixx="0"
        ixy="0"
        ixz="0"
        iyy="0"
        iyz="0"
        izz="0" />
    </inertial>
    <visual>
      <origin
        xyz="0 0 0"
        rpy="0 0 0" />
      <geometry>
        <mesh
          filename="package://arm_description/meshes/base_link.STL" />
      </geometry>
      <material
        name="">
        <color
          rgba="0.792156862745098 0.819607843137255 0.933333333333333 1" />
      </material>
    </visual>
    <collision>
      <origin
        xyz="0 0 0"
        rpy="0 0 0" />
      <geometry>
        <mesh
          filename="package://arm_description/meshes/base_link.STL" />
      </geometry>
    </collision>
  </link>
  
  <link
    name="link1">
    <inertial>
      <origin
        xyz="0.0395053712709794 0.00770230909756575 0.0284292729379571"
        rpy="0 0 0" />
      <mass
        value="0.990792255330962" />
      <inertia
        ixx="0"
        ixy="0"
        ixz="0"
        iyy="0"
        iyz="0"
        izz="0" />
    </inertial>
    <visual>
      <origin
        xyz="0 0 0"
        rpy="0 0 0" />
      <geometry>
        <mesh
          filename="package://arm_description/meshes/link1.STL" />
      </geometry>
      <material
        name="">
        <color
          rgba="0.792156862745098 0.819607843137255 0.933333333333333 1" />
      </material>
    </visual>
    <collision>
      <origin
        xyz="0 0 0"
        rpy="0 0 0" />
      <geometry>
        <mesh
          filename="package://arm_description/meshes/link1.STL" />
      </geometry>
    </collision>
  </link>
  
  <joint
    name="joint1"
    type="revolute">
    <origin
      xyz="1.11809345478857 -0.671499228198899 0.352488805901295"
      rpy="-1.5707963267949 0 3.14159265358979" />
    <parent
      link="base_link" />
    <child
      link="link1" />
    <axis
      xyz="0 0 0" />
    <limit
      lower="-3.14"
      upper="3.14"
      effort="100"
      velocity="20" />
  </joint>
  
  <link
    name="link2">
    <inertial>
      <origin
        xyz="0.207915471479058 -0.0204954389839018 0.0248850102166089"
        rpy="0 0 0" />
      <mass
        value="1.56702644768336" />
      <inertia
        ixx="0"
        ixy="0"
        ixz="0"
        iyy="0"
        iyz="0"
        izz="0" />
    </inertial>
    <visual>
      <origin
        xyz="0 0 0"
        rpy="0 0 0" />
      <geometry>
        <mesh
          filename="package://arm_description/meshes/link2.STL" />
      </geometry>
      <material
        name="">
        <color
          rgba="0.792156862745098 0.819607843137255 0.933333333333333 1" />
      </material>
    </visual>
    <collision>
      <origin
        xyz="0 0 0"
        rpy="0 0 0" />
      <geometry>
        <mesh
          filename="package://arm_description/meshes/link2.STL" />
      </geometry>
    </collision>
  </link>
  
  <joint
    name="joint2"
    type="revolute">
    <origin
      xyz="-0.0120242146656717 0.536975785334328 0.0579565358894426"
      rpy="3.14159265358979 0 -1.5707963267949" />
    <parent
      link="link1" />
    <child
      link="link2" />
    <axis
      xyz="0 0 0" />
    <limit
      lower="-3.14"
      upper="3.14"
      effort="100"
      velocity="20" />
  </joint>
  
  <link
    name="link3">
    <inertial>
      <origin
        xyz="0.0103146450264884 0.00463587622434214 -0.253568156076182"
        rpy="0 0 0" />
      <mass
        value="4.49311908049434" />
      <inertia
        ixx="0.011285085138619"
        ixy="-5.8451240418789E-05"
        ixz="0.000418543816314045"
        iyy="0.0110850262405422"
        iyz="0.00154585606360207"
        izz="0.000231710493344002" />
    </inertial>
    <visual>
      <origin
        xyz="0 0 0"
        rpy="0 0 0" />
      <geometry>
        <mesh
          filename="package://arm_description/meshes/link3.STL" />
      </geometry>
      <material
        name="">
        <color
          rgba="0.898039215686275 0.917647058823529 0.929411764705882 1" />
      </material>
    </visual>
    <collision>
      <origin
        xyz="0 0 0"
        rpy="0 0 0" />
      <geometry>
        <mesh
          filename="package://arm_description/meshes/link3.STL" />
      </geometry>
    </collision>
  </link>
  
  <joint
    name="joint3"
    type="revolute">
    <origin
      xyz="0.0173266017706057 0.0706491835637237 -0.0599999999999999"
      rpy="-1.5707963267949 0 3.14159265358979" />
    <parent
      link="link2" />
    <child
      link="link3" />
    <axis
      xyz="0 0 0" />
    <limit
      lower="-3.14"
      upper="3.14"
      effort="100"
      velocity="20" />
  </joint>
  
  <link
    name="link4">
    <inertial>
      <origin
        xyz="-0.0140455165710528 -0.127140183941276 0.0132073879549877"
        rpy="0 0 0" />
      <mass
        value="0.738531576468679" />
      <inertia
        ixx="0"
        ixy="0"
        ixz="0"
        iyy="0"
        iyz="0"
        izz="0" />
    </inertial>
    <visual>
      <origin
        xyz="0 0 0"
        rpy="0 0 0" />
      <geometry>
        <mesh
          filename="package://arm_description/meshes/link4.STL" />
      </geometry>
      <material
        name="">
        <color
          rgba="0.792156862745098 0.819607843137255 0.933333333333333 1" />
      </material>
    </visual>
    <collision>
      <origin
        xyz="0 0 0"
        rpy="0 0 0" />
      <geometry>
        <mesh
          filename="package://arm_description/meshes/link4.STL" />
      </geometry>
    </collision>
  </link>
  
  <joint
    name="joint4"
    type="revolute">
    <origin
      xyz="-0.139051207414672 0.0269999999998711 -0.500002721588281"
      rpy="-1.57079632679495 -1.38777878078144E-15 -3.14159265358979" />
    <parent
      link="link3" />
    <child
      link="link4" />
    <axis
      xyz="0 0 0" />
    <limit
      lower="-3.14"
      upper="3.14"
      effort="100"
      velocity="20" />
  </joint>
  
  <link
    name="link5">
    <inertial>
      <origin
        xyz="0.0766095654706823 0.0198118512247197 -0.0335271292413999"
        rpy="0 0 0" />
      <mass
        value="0.583439980133474" />
      <inertia
        ixx="0"
        ixy="0"
        ixz="0"
        iyy="0"
        iyz="0"
        izz="0" />
    </inertial>
    <visual>
      <origin
        xyz="0 0 0"
        rpy="0 0 0" />
      <geometry>
        <mesh
          filename="package://arm_description/meshes/link5.STL" />
      </geometry>
      <material
        name="">
        <color
          rgba="0.792156862745098 0.819607843137255 0.933333333333333 1" />
      </material>
    </visual>
    <collision>
      <origin
        xyz="0 0 0"
        rpy="0 0 0" />
      <geometry>
        <mesh
          filename="package://arm_description/meshes/link5.STL" />
      </geometry>
    </collision>
  </link>
  
  <joint
    name="joint5"
    type="revolute">
    <origin
      xyz="-0.00121372676860452 -0.136002721588221 -0.178639022428853"
      rpy="1.5707963267949 -1.5707963267949 0" />
    <parent
      link="link4" />
    <child
      link="link5" />
    <axis
      xyz="0 0 0" />
    <limit
      lower="-3.14"
      upper="3.14"
      effort="100"
      velocity="20" />
  </joint>
  
  <link
    name="link6">
    <inertial>
      <origin
        xyz="0.0149443387825755 0.039468715313824 0.0444532167608513"
        rpy="0 0 0" />
      <mass
        value="0.868249563215015" />
      <inertia
        ixx="0.00312646246030417"
        ixy="-2.30420803322864E-05"
        ixz="-1.26038502551463E-18"
        iyy="0.00151709665423134"
        iyz="-1.67461801803964E-16"
        izz="0.00457880133964684" />
    </inertial>
    <visual>
      <origin
        xyz="0 0 0"
        rpy="0 0 0" />
      <geometry>
        <mesh
          filename="package://arm_description/meshes/link6.STL" />
      </geometry>
      <material
        name="">
        <color
          rgba="0.752941176470588 0.752941176470588 0.752941176470588 1" />
      </material>
    </visual>
    <collision>
      <origin
        xyz="0 0 0"
        rpy="0 0 0" />
      <geometry>
        <mesh
          filename="package://arm_description/meshes/link6.STL" />
      </geometry>
    </collision>
  </link>
  
  <joint
    name="joint6"
    type="revolute">
    <origin
      xyz="0.118092239189695 0.0226342752571765 -0.135417585180578"
      rpy="-1.5707963267949 1.38777878078144E-15 1.5707963267949" />
    <parent
      link="link5" />
    <child
      link="link6" />
    <axis
      xyz="0 0 0" />
    <limit
      lower="-3.14"
      upper="3.14"
      effort="100"
      velocity="20" />
  </joint>

  <transmission name="tran1">
    <type>transmission_interface/SimpleTransmission</type>
    <joint name="joint1">
      <hardwareInterface>hardware_interface/EffortJointInterface</hardwareInterface>
    </joint>
    <actuator name="motor1">
      <hardwareInterface>hardware_interface/EffortJointInterface</hardwareInterface>
      <mechanicalReduction>1</mechanicalReduction>
    </actuator>
  </transmission>

  <transmission name="tran2">
    <type>transmission_interface/SimpleTransmission</type>
    <joint name="joint2">
      <hardwareInterface>hardware_interface/EffortJointInterface</hardwareInterface>
    </joint>
    <actuator name="motor2">
      <hardwareInterface>hardware_interface/EffortJointInterface</hardwareInterface>
      <mechanicalReduction>1</mechanicalReduction>
    </actuator>
  </transmission>

  <transmission name="tran3">
    <type>transmission_interface/SimpleTransmission</type>
    <joint name="joint3">
      <hardwareInterface>hardware_interface/EffortJointInterface</hardwareInterface>
    </joint>
    <actuator name="motor3">
      <hardwareInterface>hardware_interface/EffortJointInterface</hardwareInterface>
      <mechanicalReduction>1</mechanicalReduction>
    </actuator>
  </transmission>

  <transmission name="tran4">
    <type>transmission_interface/SimpleTransmission</type>
    <joint name="joint4">
      <hardwareInterface>hardware_interface/EffortJointInterface</hardwareInterface>
    </joint>
    <actuator name="motor4">
      <hardwareInterface>hardware_interface/EffortJointInterface</hardwareInterface>
      <mechanicalReduction>1</mechanicalReduction>
    </actuator>
  </transmission>

  <transmission name="tran5">
    <type>transmission_interface/SimpleTransmission</type>
    <joint name="joint5">
      <hardwareInterface>hardware_interface/EffortJointInterface</hardwareInterface>
    </joint>
    <actuator name="motor5">
      <hardwareInterface>hardware_interface/EffortJointInterface</hardwareInterface>
      <mechanicalReduction>1</mechanicalReduction>
    </actuator>
  </transmission>

  <transmission name="tran6">
    <type>transmission_interface/SimpleTransmission</type>
    <joint name="joint6">
      <hardwareInterface>hardware_interface/EffortJointInterface</hardwareInterface>
    </joint>
    <actuator name="motor6">
      <hardwareInterface>hardware_interface/EffortJointInterface</hardwareInterface>
      <mechanicalReduction>1</mechanicalReduction>
    </actuator>
  </transmission>

  <gazebo>
    <plugin name="gazebo_ros_control" filename="libgazebo_ros_control.so">
    </plugin>
  </gazebo>


</robot>
